<?xml version="1.0"?>
<robot name="slam_bot" xmlns:xacro="http://ros.org/wiki/xacro">
    <!-- Define robot constants -->
    <xacro:property name="base_width" value="0.385" />
    <xacro:property name="base_length" value="0.27" />
    <xacro:property name="base_height" value="0.10" />

    <xacro:property name="wheel_radius" value="0.027" />
    <xacro:property name="wheel_width" value="0.026" />
    <xacro:property name="wheel_ygap" value="0.065" />
    <xacro:property name="wheel_zoff" value="0.055" />
    <xacro:property name="wheel_xoff" value="0" />

    <xacro:property name="caster_xoff" value="0.12" />

    <xacro:property name="lidar_xoff" value="0.07" />
    <xacro:property name="lidar_zoff" value="0.13" />
    <xacro:property name="lidar_yaw" value="3.1415" />

    <!-- Robot Base -->
    <link name="base_link">
        <visual>
            <geometry>
                <box size="${base_length} ${base_width} ${base_height}" />
            </geometry>
            <material name="Blue">
                <color rgba="0 1.0 1.0 1.0" />
            </material>
        </visual>
    </link>

    <!-- Robot Footprint -->
    <link name="base_footprint" />

    <joint name="base_joint" type="fixed">
        <parent link="base_link" />
        <child link="base_footprint" />
        <origin xyz="0.0 0.0 ${-(wheel_radius+wheel_zoff)}" rpy="0 0 0" />
    </joint>

    <!-- Wheels -->
    <xacro:macro name="wheel" params="prefix x_reflect y_reflect">
        <link name="${prefix}_link">
            <visual>
                <origin xyz="0 0 0" rpy="${pi/2} 0 0" />
                <geometry>
                    <cylinder radius="${wheel_radius}" length="${wheel_width}" />
                </geometry>
                <material name="Black">
                    <color rgba="0.5 0.5 0.5 1.0" />
                </material>
            </visual>
        </link>

        <joint name="${prefix}_joint" type="continuous">
            <parent link="base_link" />
            <child link="${prefix}_link" />
            <origin
                xyz="${x_reflect*wheel_xoff} ${y_reflect*(base_width/2-wheel_ygap)} ${-wheel_zoff}"
                rpy="0 0 0" />
            <axis xyz="0 1 0" />
        </joint>
    </xacro:macro>

    <xacro:wheel prefix="drivewhl_l" x_reflect="-1" y_reflect="1" />
    <xacro:wheel prefix="drivewhl_r" x_reflect="-1" y_reflect="-1" />

    <!-- Front Caster Wheel -->
    <link name="front_caster">
        <visual>
            <geometry>
                <sphere radius="${(wheel_radius+wheel_zoff-(base_height/2))}" />
            </geometry>
            <material name="Grey">
                <color rgba="0 1.0 1.0 1.0" />
            </material>
        </visual>
    </link>

    <!--Back
    Caster Wheel -->
    <link name="back_caster">
        <visual>
            <geometry>
                <sphere radius="${(wheel_radius+wheel_zoff-(base_height/2))}" />
            </geometry>
            <material name="Grey">
                <color rgba="0 1.0 1.0 1.0" />
            </material>
        </visual>
    </link>

    <joint name="front_caster_joint" type="fixed">
        <parent link="base_link" />
        <child link="front_caster" />
        <origin xyz="${caster_xoff} 0.0 ${-(base_height/2)}" rpy="0 0 0" />
    </joint>

    <joint name="back_caster_joint" type="fixed">
        <parent link="base_link" />
        <child link="back_caster" />
        <origin xyz="${-caster_xoff} 0.0 ${-(base_height/2)}" rpy="0 0 0" />
    </joint>

    <!-- LiDAR -->
    <link name="laser">
        <visual>
            <origin xyz="0 0 0" rpy="0 0 0" />
            <geometry>
                <cylinder radius="0.0508" length="0.055" />
            </geometry>
        </visual>
    </link>

    <joint name="lidar_joint" type="fixed">
        <parent link="base_link" />
        <child link="laser" />
        <origin xyz="${lidar_xoff} 0 ${lidar_zoff}" rpy="0 0 ${lidar_yaw}" />
    </joint>
</robot>